Workbook

Sheet 85表7個別因素清冊格式
A1: 表7 宗地個別因素清冊
A2: 興辦事業計畫名稱：○○○○○○○○○○○○○○○○ | N2: 案號: | O2: 1040301-○○-○○○
A3: 0基本資料 | C3: 宗地流水號 | D3: 0001 | E3: 0002 | F3: 0002-01 | G3: 0002-02 | H3: 0002-03 | I3: 0002-04 | J3: 0003 | K3: 0004 | L3: 0005 | M3: 0006 | N3: 0006-01 | O3: 0006-02 | P3: 0007 | Q3: 0008
C4: 鄉鎮市區 | D4: ○○鄉 | E4: ○○鄉 | F4: ○○鄉 | G4: ○○鄉 | H4: ○○鄉 | I4: ○○鄉 | J4: ○○鄉 | K4: ○○鄉 | L4: ○○鄉 | M4: ○○鄉 | N4: ○○鄉 | O4: ○○鄉 | P4: ○○鄉 | Q4: ○○鄉
C5: 段小段名稱 | D5: ○○段○○小段 | E5: ○○段○○小段 | F5: ○○段○○小段 | G5: ○○段○○小段 | H5: ○○段○○小段 | I5: ○○段○○小段 | J5: ○○段○○小段 | K5: ○○段○○小段 | L5: ○○段○○小段 | M5: ○○段○○小段 | N5: ○○段○○小段 | O5: ○○段○○小段 | P5: ○○段○○小段 | Q5: ○○段○○小段
C6: 地號 | D6: 30 | E6: 31等 | F6: 31 | G6: 31-1 | H6: 31-2 | I6: 31-3 | J6: 32 | K6: 33 | L6: 34 | M6: 35等 | N6: 35 | O6: 35-1 | P6: 36 | Q6: 37
C7: 土地所有權人或管理人姓名 | D7: 甲一 | E7: 乙二 | F7: 乙二 | G7: 乙二 | H7: 乙二 | I7: 乙二 | J7: 乙二 | K7: 丙三等3人 | L7: 甲一 | M7: 丁四等4人 | N7: 丁四等4人 | O7: 丁四等4人 | P7: 丙三等3人 | Q7: 丙三等3人
A8: 1.宗地條件 | B8: 7 | C8: 面積(M2) | D8: 878 | E8: =SUM(F8:I8) -> 530 | F8: 210 | G8: 120 | H8: 110 | I8: 90 | J8: 4456 | K8: 850 | L8: 330 | M8: 952 | N8: 609 | O8: 343 | P8: 363 | Q8: 360
B9: 8 | C9: 寬度(M) | D9: 15 | E9: 22 | J9: 57 | K9: 60 | L9: 15 | M9: 33 | P9: 30 | Q9: 30
B10: 9 | C10: 深度(M) | D10: 59 | E10: 24 | J10: 51 | K10: 10 | L10: 22 | M10: 29 | P10: 12 | Q10: 12
B11: 10 | C11: 形狀 | D11: 方形 | E11: 方形 | J11: 不規則形 | K11: 不規則形 | L11: 方形 | M11: 方形 | P11: 方形 | Q11: 方形
B12: 11 | C12: 臨街情形 | D12: 單面臨街 | E12: 單面臨街 | J12: 非臨街地 | K12: 非臨街地 | L12: 單面臨街 | M12: 單面臨街 | P12: 單面臨街 | Q12: 非臨街地
B13: 12 | C13: 地勢 | D13: 平坦 | E13: 低窪 | J13: 高亢 | K13: 平坦 | L13: 平坦 | M13: 平坦 | P13: 平坦 | Q13: 平坦
A14: 2.道路條件 | B14: 13 | C14: 道路種類 | D14: 農路 | E14: 農路 | J14: 無 | K14: 無 | L14: 農路 | M14: 農路 | P14: 農路 | Q14: 無
B15: 14 | C15: 面前道路寬度 | D15: 6 | E15: 6 | J15: 無 | K15: 無 | L15: 6 | M15: 4 | P15: 4 | Q15: 無
A16: 3.接近條件 | B16: 15 | C16: 學校名稱 | D16: ○○ | E16: ○○ | J16: ○○ | K16: ○○ | L16: ○○ | M16: ○○ | P16: ○○ | Q16: ○○
C17: 接近學校之程度(M) | D17: 1020 | E17: 1060 | J17: 1100 | K17: 1030 | L17: 1045 | M17: 1040 | P17: 1030 | Q17: 1030
B18: 16 | C18: 市場名稱 | D18: ○○ | E18: ○○ | J18: ○○ | K18: ○○ | L18: ○○ | M18: ○○ | P18: ○○ | Q18: ○○
C19: 接近市場之程度(M) | D19: 1055 | E19: 1045 | J19: 1060 | K19: 1010 | L19: 1030 | M19: 1050 | P19: 1010 | Q19: 1010
B20: 17 | C20: 公園、廣場名稱 | D20: ○○ | E20: ○○ | J20: ○○ | K20: ○○ | L20: ○○ | M20: ○○ | P20: ○○ | Q20: ○○
C21: 接近公園、廣場之程度(M) | D21: 1040 | E21: 1050 | J21: 1030 | K21: 1100 | L21: 1050 | M21: 1030 | P21: 1100 | Q21: 1100
B22: 18 | C22: 車站名稱 | D22: ○○ | E22: ○○ | J22: ○○ | K22: ○○ | L22: ○○ | M22: ○○ | P22: ○○ | Q22: ○○
C23: 接近車站之程度(M) | D23: 1005 | E23: 995 | J23: 1010 | K23: 960 | L23: 980 | M23: 1000 | P23: 960 | Q23: 960
B24: 19 | C24: 商圈名稱 | D24: ○○ | E24: ○○ | J24: ○○ | K24: ○○ | L24: ○○ | M24: ○○ | P24: ○○ | Q24: ○○
C25: 接近商圈之程度(M) | D25: 1055 | E25: 1045 | J25: 1060 | K25: 1010 | L25: 1030 | M25: 1050 | P25: 1010 | Q25: 1010
A26: 4.周邊環境條件 | B26: 20 | C26: 嫌惡設施名稱 | D26: ○○垃圾焚化場 | E26: ○○垃圾焚化場 | J26: ○○垃圾焚化場 | K26: ○○垃圾焚化場 | L26: ○○垃圾焚化場 | M26: ○○垃圾焚化場 | P26: ○○垃圾焚化場 | Q26: ○○垃圾焚化場
C27: 接近嫌惡設施之程度（M） | D27: 2400 | E27: 2450 | J27: 3000 | K27: 2480 | L27: 2495 | M27: 2500 | P27: 2480 | Q27: 2480
B28: 21 | C28: 停車方便性 | D28: - | E28: - | J28: - | K28: - | L28: - | M28: - | P28: - | Q28: -
A29: 5.行政條件 | B29: 22 | C29: 使用分區或編定用地 | D29: 農牧用地 | E29: 農牧用地 | F29: 農牧用地 | G29: 農牧用地 | H29: 農牧用地 | I29: 農牧用地 | J29: 林業用地 | K29: 農牧用地 | L29: 農牧用地 | M29: 農牧用地 | N29: 農牧用地 | O29: 農牧用地 | P29: 農牧用地 | Q29: 農牧用地
B30: 23 | C30: 建蔽率(%) | D30: - | E30: - | J30: - | K30: - | L30: - | M30: - | P30: - | Q30: -
B31: 24 | C31: 容積率(%) | D31: - | E31: - | J31: - | K31: - | L31: - | M31: - | P31: - | Q31: -
B32: 25 | C32: 有無禁、限建 | D32: 無 | E32: 無 | J32: 無 | K32: 無 | L32: 無 | M32: 無 | P32: 無 | Q32: 無
C33: 禁、限建情形 | D33: 無 | E33: 無 | J33: 無 | K33: 無 | L33: 無 | M33: 無 | P33: 無 | Q33: 無
A34: 6.其他
A35: 協議價購程序 | B35: □尚未辦理 ■已辦理，未達成協議之金額(元/M2)如右 | D35: 14500 | F35: 14500 | G35: 14500 | H35: 14500 | I35: 14500 | J35: 14500 | K35: 14500 | L35: 14500 | N35: 14500 | O35: 14500 | P35: 14500 | Q35: 14500
A36: 填寫日期：○○年○○月○○日 ○○機關（即需用土地人）核章：承辦人 單位主管： 首長：

Sheet 86個別因素清冊附表參考格式1
A1: 共有土地共有人及對應持分附表
A2: 興辦事業計畫名稱：
A3: 宗地流水號 | B3: 0004 | D3: 0006-01 | E3: 0006-02 | F3: 0007 | G3: 0008
D4: 合併為0006
A5: 鄉鎮市區 | B5: ○○ | D5: ○○ | E5: ○○ | F5: ○○ | G5: ○○
A6: 段小段名稱 | B6: ○○段○○小段 | D6: ○○段○○小段 | E6: ○○段○○小段 | F6: ○○段○○小段 | G6: ○○段○○小段
A7: 地號 | B7: 33 | D7: 35 | E7: 35-1 | F7: 36 | G7: 37
A8: 土地所有權人或管理人 | B8: 丙三等3人 | D8: 丁四等4人 | E8: 丁四等4人 | F8: 丙三等3人 | G8: 丙三等3人
B9: 持分 | D9: 持分 | E9: 持分 | F9: 持分 | G9: 持分
A10: 丙三 | B10: 1/2 | F10: 1/2 | G10: 1/4
A11: 丁四 | B11: 1/4 | D11: 1/4 | E11: 1/4 | F11: 1/4 | G11: 1/2
A12: 丁五 | B12: 1/4 | D12: 1/4 | E12: 1/4 | F12: 1/4 | G12: 1/4
A13: 丁一 | D13: 1/4 | E13: 1/4
A14: 丁二 | D14: 1/4 | E14: 1/4

Sheet 88表1-1買賣實例1-土地
A1: 表1-1 買賣實例調查估價表 | I1: 年期： | J1: 1040301 | K1: 地價區段號：P010-00 | L1: 實例編號： | N1: 1
A2: 基本資料 | J2: 成 本 價 格 計 算
A3: 實例門牌 | D3: =[1]比較!G5 -> 台北市中山區XX段X小段XXX地號 | J3: 營造施工費標準單價(元/M2) | M3: 0
A4: 基地坐落 | D4: ○○市○○區○○段○○小段○○地號 | J4: 調整單價率 | L4: 1 | M4: 交易日期 | N4: 103年10月5日
A5: 建號 | D5: 0 | E5: 主要構造種類 | H5: 0 | J5: 1.營造或施工費調整單價(元/M2) | M5: =M3*L4 -> 0
A6: 總樓層數 | D6: 0 | E6: 實例登記面積 | H6: 0 | I6: M2 | J6: 2.規劃設計費 | K6: :為營造施工費之 | L6: 0.028 | M6: =M5*L6 -> 0
C7: 地下層數 | D7: 0 | E7: 實例計算面積(扣除車位) | H7: 0 | I7: M2 | J7: 3.廣告費銷售費 | K7: :實例總成本之 | L7: 0.045 | M7: =(M5+M6)*L7*(1+L10)*(1+L11)/(1-(L7+L8+L9)*(1+L10)*(1+L11)) -> 0
A8: 移轉樓層 | C8: 地上第 | D8: 0 | E8: 建築工期 | H8: 0 | I8: 年 | J8: 4.管理費 | K8: :實例總成本之 | L8: 0.045 | M8: =(M5+M6)*L8*(1+L10)*(1+L11)/(1-(L7+L8+L9)*(1+L10)*(1+L11)) -> 0
A9: 資本利息綜合利率計算 | B9: 資金來源 | D9: 利率 | E9: 資金比例 | G9: 加權平均利率 | J9: 5.稅捐及其他負擔 | K9: :實例總成本之 | L9: 0.012 | M9: =(M5+M6)*L9*(1+L10)*(1+L11)/(1-(L7+L8+L9)*(1+L10)*(1+L11)) -> 0
B10: 自有資金 | D10: 0.0134 | E10: 0.4 | G10: =D10*E10 -> 0.00536 | I10: =G10+G11+G12 -> 0.01684 | J10: 6.資本利息 | K10: 資本利息綜合利率 | L10: =I10*G13*H8 -> 0 | M10: =(M5+M6+M7+M8+M9)*L10 -> 0
B11: 借貸資金 | D11: 0.0287 | E11: 0.4 | G11: =D11*E11 -> 0.01148 | J11: 7.開發或建築利潤 | K11: :為累計投入額之 | L11: 0.12 | M11: =(M5+M6+M7+M8+M9+M10)*L11 -> 0
B12: 預售收入 | D12: 0 | E12: 0.2 | G12: =D12*E12 -> 0 | J12: 實例重建成本(元/M2) | M12: =(M5+M6+M7+M8+M9)+M10+M11 -> 0
B13: 分期投入資本數額及年數調整 | G13: 0.5 | J13: 實例建物成本價格(元/M2) | M13: =M12-F20 -> #DIV/0!
A14: 累 積 折 舊 額 | J14: 地上■無建築改良物 □有建築改良物(□區分所有建物□全部層數)
A15: 建築完成年月 | D15: 已經歷年數 | F15: 剩餘耐用年數 | H15: 總耐用年數 | J15: 買賣實例總價格(元) | M15: 121000000
B16: / | J16: 正常買賣總價格(元) | M16: =M15+N21+N22+N24 -> 121000000
A17: 折舊方法 | D17: 定額法 | F17: 殘餘價格率 | H17: 0.1
A18: 計 算 式 | D18: 重建成本× (1-殘價率)÷總耐用年數×已經歷年數 | J18: 土地面積(M2) | M18: 130
A20: 累積折舊額(元/M2) | F20: =(1-H17)/H16*D16*M12 -> #DIV/0! | J20: 土地正常買賣單價(元/M2) | M20: =ROUND(M16/M18,0) -> 930769
A21: 備註欄 | B21: 1.本實例移轉樓層房價(元/坪)： | H21: =M16/H7*3.3058 -> #DIV/0! | J21: 第7條、第8條修正說明及修正數： | K21: - | N21: 0
B22: 2.本實例營造單價（元/坪）： | K22: - | N22: 0
K23: - | N23: 0
K24: - | N24: 0
A25: 填寫日期： 年 月 日 承辦員： 課（股）長： 主任（局、處長）：
K26: 不動產估價師：

Sheet 89表1-1買賣實例1-土地 (1)
A1: 表1-1 買賣實例調查估價表 | I1: 年期： | J1: 1040301 | K1: 地價區段號：P101-00 | L1: 實例編號： | N1: 34
A2: 基本資料 | J2: 成 本 價 格 計 算
A3: 實例門牌 | D3: =[1]比較!G5 -> 台北市中山區XX段X小段XXX地號 | J3: 營造施工費標準單價(元/M2) | M3: 0
A4: 基地坐落 | D4: ○○市○○區○○段○○小段○○地號 | J4: 調整單價率 | L4: 1 | M4: 交易日期 | N4: 103年12月18日
A5: 建號 | D5: 0 | E5: 主要構造種類 | H5: 0 | J5: 1.營造或施工費調整單價(元/M2) | M5: =M3*L4 -> 0
A6: 總樓層數 | C6: 地上層數 | D6: 0 | E6: 實例登記面積 | H6: 0 | I6: M2 | J6: 2.規劃設計費 | K6: :為營造施工費之 | L6: 0.028 | M6: =M5*L6 -> 0
C7: 地下層數 | D7: 0 | E7: 實例計算面積(扣除車位) | H7: 0 | I7: M2 | J7: 3.廣告費銷售費 | K7: :實例總成本之 | L7: 0.045 | M7: =(M5+M6)*L7*(1+L10)*(1+L11)/(1-(L7+L8+L9)*(1+L10)*(1+L11)) -> 0
A8: 移轉樓層 | C8: 地上第 | D8: 0 | E8: 建築工期 | H8: 0 | I8: 年 | J8: 4.管理費 | K8: :實例總成本之 | L8: 0.045 | M8: =(M5+M6)*L8*(1+L10)*(1+L11)/(1-(L7+L8+L9)*(1+L10)*(1+L11)) -> 0
A9: 資本利息綜合利率計算 | B9: 資金來源 | D9: 利率 | E9: 資金比例 | G9: 加權平均利率 | J9: 5.稅捐及其他負擔 | K9: :實例總成本之 | L9: 0.012 | M9: =(M5+M6)*L9*(1+L10)*(1+L11)/(1-(L7+L8+L9)*(1+L10)*(1+L11)) -> 0
B10: 自有資金 | D10: 0.0134 | E10: 0.4 | G10: =D10*E10 -> 0.00536 | I10: =G10+G11+G12 -> 0.01684 | J10: 6.資本利息 | K10: 資本利息綜合利率 | L10: =I10*G13*H8 -> 0 | M10: =(M5+M6+M7+M8+M9)*L10 -> 0
B11: 借貸資金 | D11: 0.0287 | E11: 0.4 | G11: =D11*E11 -> 0.01148 | J11: 7.開發或建築利潤 | K11: :為累計投入額之 | L11: 0.12 | M11: =(M5+M6+M7+M8+M9+M10)*L11 -> 0
B12: 預售收入 | D12: 0 | E12: 0.2 | G12: =D12*E12 -> 0 | J12: 實例重建成本(元/M2) | M12: =(M5+M6+M7+M8+M9)+M10+M11 -> 0
B13: 分期投入資本數額及年數調整 | G13: 0.5 | J13: 實例建物成本價格(元/M2) | M13: =M12-F20 -> #DIV/0!
A14: 累 積 折 舊 額 | J14: 地上■無建築改良物 □有建築改良物(□區分所有建物□全部層數)
A15: 建築完成年月 | D15: 已經歷年數 | F15: 剩餘耐用年數 | H15: 總耐用年數 | J15: 買賣實例總價格(元) | M15: 9424000
A16: 100 | B16: / | C16: 3 | J16: 正常買賣總價格(元) | M16: =M15+N21+N22+N24 -> 9424000
A17: 折舊方法 | D17: 定額法 | F17: 殘餘價格率 | H17: 0.1
A18: 計 算 式 | D18: 重建成本× (1-殘價率)÷總耐用年數×已經歷年數 | J18: 土地面積(M2) | M18: 620
A20: 累積折舊額(元/M2) | F20: =(1-H17)/H16*D16*M12 -> #DIV/0! | J20: 土地正常買賣單價(元/M2) | M20: =ROUND(M16/M18,0) -> 15200
A21: 備註欄 | B21: 1.本實例移轉樓層房價(元/坪)： | H21: =M16/H7*3.3058 -> #DIV/0! | J21: 第7條、第8條修正說明及修正數： | K21: - | N21: 0
B22: 2.本實例營造單價（元/坪）： | K22: - | N22: 0
K23: - | N23: 0
K24: - | N24: 0
A25: 填寫日期： 年 月 日 承辦員： 課（股）長： 主任（局、處長）：
K26: 不動產估價師：

Sheet 90表1-1買賣實例1-土地 (2)
A1: 表1-1 買賣實例調查估價表 | I1: 年期： | J1: 1040301 | K1: 地價區段號：P102-00 | L1: 實例編號： | N1: 56
A2: 基本資料 | J2: 成 本 價 格 計 算
A3: 實例門牌 | D3: =[1]比較!G5 -> 台北市中山區XX段X小段XXX地號 | J3: 營造施工費標準單價(元/M2) | M3: 0
A4: 基地坐落 | D4: ○○市○○區○○段○○小段○○地號 | J4: 調整單價率 | L4: 1 | M4: 交易日期 | N4: 103年11月9日
A5: 建號 | D5: 0 | E5: 主要構造種類 | H5: 0 | J5: 1.營造或施工費調整單價(元/M2) | M5: =M3*L4 -> 0
A6: 總樓層數 | C6: 地上層數 | D6: 0 | E6: 實例登記面積 | H6: 0 | I6: M2 | J6: 2.規劃設計費 | K6: :為營造施工費之 | L6: 0.028 | M6: =M5*L6 -> 0
C7: 地下層數 | D7: 0 | E7: 實例計算面積(扣除車位) | H7: 0 | I7: M2 | J7: 3.廣告費銷售費 | K7: :實例總成本之 | L7: 0.045 | M7: =(M5+M6)*L7*(1+L10)*(1+L11)/(1-(L7+L8+L9)*(1+L10)*(1+L11)) -> 0
A8: 移轉樓層 | C8: 地上第 | D8: 0 | E8: 建築工期 | H8: 0 | I8: 年 | J8: 4.管理費 | K8: :實例總成本之 | L8: 0.045 | M8: =(M5+M6)*L8*(1+L10)*(1+L11)/(1-(L7+L8+L9)*(1+L10)*(1+L11)) -> 0
A9: 資本利息綜合利率計算 | B9: 資金來源 | D9: 利率 | E9: 資金比例 | G9: 加權平均利率 | J9: 5.稅捐及其他負擔 | K9: :實例總成本之 | L9: 0.012 | M9: =(M5+M6)*L9*(1+L10)*(1+L11)/(1-(L7+L8+L9)*(1+L10)*(1+L11)) -> 0
B10: 自有資金 | D10: 0.0134 | E10: 0.4 | G10: =D10*E10 -> 0.00536 | I10: =G10+G11+G12 -> 0.01684 | J10: 6.資本利息 | K10: 資本利息綜合利率 | L10: =I10*G13*H8 -> 0 | M10: =(M5+M6+M7+M8+M9)*L10 -> 0
B11: 借貸資金 | D11: 0.0287 | E11: 0.4 | G11: =D11*E11 -> 0.01148 | J11: 7.開發或建築利潤 | K11: :為累計投入額之 | L11: 0.12 | M11: =(M5+M6+M7+M8+M9+M10)*L11 -> 0
B12: 預售收入 | D12: 0 | E12: 0.2 | G12: =D12*E12 -> 0 | J12: 實例重建成本(元/M2) | M12: =(M5+M6+M7+M8+M9)+M10+M11 -> 0
B13: 分期投入資本數額及年數調整 | G13: 0.5 | J13: 實例建物成本價格(元/M2) | M13: =M12-F20 -> #DIV/0!
A14: 累 積 折 舊 額 | J14: 地上■無建築改良物 □有建築改良物(□區分所有建物□全部層數)
A15: 建築完成年月 | D15: 已經歷年數 | F15: 剩餘耐用年數 | H15: 總耐用年數 | J15: 買賣實例總價格(元) | M15: 20925000
A16: 100 | B16: / | C16: 3 | J16: 正常買賣總價格(元) | M16: =M15+N21+N22+N24 -> 20925000
A17: 折舊方法 | D17: 定額法 | F17: 殘餘價格率 | H17: 0.1
A18: 計 算 式 | D18: 重建成本× (1-殘價率)÷總耐用年數×已經歷年數 | J18: 土地面積(M2) | M18: 1550
A20: 累積折舊額(元/M2) | F20: =(1-H17)/H16*D16*M12 -> #DIV/0! | J20: 土地正常買賣單價(元/M2) | M20: =ROUND(M16/M18,0) -> 13500
A21: 備註欄 | B21: 1.本實例移轉樓層房價(元/坪)： | H21: =M16/H7*3.3058 -> #DIV/0! | J21: 第7條、第8條修正說明及修正數： | K21: - | N21: 0
B22: 2.本實例營造單價（元/坪）： | K22: - | N22: 0
K23: - | N23: 0
K24: - | N24: 0
A25: 填寫日期： 年 月 日 承辦員： 課（股）長： 主任（局、處長）：
K26: 不動產估價師：

Sheet 91表1-1買賣實例1-土地 (3)
A1: 表1-1 買賣實例調查估價表 | I1: 年期： | J1: 1040301 | K1: 地價區段號：P103-00 | L1: 實例編號： | N1: 78
A2: 基本資料 | J2: 成 本 價 格 計 算
A3: 實例門牌 | D3: =[1]比較!G5 -> 台北市中山區XX段X小段XXX地號 | J3: 營造施工費標準單價(元/M2) | M3: 0
A4: 基地坐落 | D4: ○○市○○區○○段○○小段○○地號 | J4: 調整單價率 | L4: 1 | M4: 交易日期 | N4: 103年10月23日
A5: 建號 | D5: 0 | E5: 主要構造種類 | H5: 0 | J5: 1.營造或施工費調整單價(元/M2) | M5: =M3*L4 -> 0
A6: 總樓層數 | C6: 地上層數 | D6: 0 | E6: 實例登記面積 | H6: 0 | I6: M2 | J6: 2.規劃設計費 | K6: :為營造施工費之 | L6: 0.028 | M6: =M5*L6 -> 0
C7: 地下層數 | D7: 0 | E7: 實例計算面積(扣除車位) | H7: 0 | I7: M2 | J7: 3.廣告費銷售費 | K7: :實例總成本之 | L7: 0.045 | M7: =(M5+M6)*L7*(1+L10)*(1+L11)/(1-(L7+L8+L9)*(1+L10)*(1+L11)) -> 0
A8: 移轉樓層 | C8: 地上第 | D8: 0 | E8: 建築工期 | H8: 0 | I8: 年 | J8: 4.管理費 | K8: :實例總成本之 | L8: 0.045 | M8: =(M5+M6)*L8*(1+L10)*(1+L11)/(1-(L7+L8+L9)*(1+L10)*(1+L11)) -> 0
A9: 資本利息綜合利率計算 | B9: 資金來源 | D9: 利率 | E9: 資金比例 | G9: 加權平均利率 | J9: 5.稅捐及其他負擔 | K9: :實例總成本之 | L9: 0.012 | M9: =(M5+M6)*L9*(1+L10)*(1+L11)/(1-(L7+L8+L9)*(1+L10)*(1+L11)) -> 0
B10: 自有資金 | D10: 0.0134 | E10: 0.4 | G10: =D10*E10 -> 0.00536 | I10: =G10+G11+G12 -> 0.01684 | J10: 6.資本利息 | K10: 資本利息綜合利率 | L10: =I10*G13*H8 -> 0 | M10: =(M5+M6+M7+M8+M9)*L10 -> 0
B11: 借貸資金 | D11: 0.0287 | E11: 0.4 | G11: =D11*E11 -> 0.01148 | J11: 7.開發或建築利潤 | K11: :為累計投入額之 | L11: 0.12 | M11: =(M5+M6+M7+M8+M9+M10)*L11 -> 0
B12: 預售收入 | D12: 0 | E12: 0.2 | G12: =D12*E12 -> 0 | J12: 實例重建成本(元/M2) | M12: =(M5+M6+M7+M8+M9)+M10+M11 -> 0
B13: 分期投入資本數額及年數調整 | G13: 0.5 | J13: 實例建物成本價格(元/M2) | M13: =M12-F20 -> #DIV/0!
A14: 累 積 折 舊 額 | J14: 地上■無建築改良物 □有建築改良物(□區分所有建物□全部層數)
A15: 建築完成年月 | D15: 已經歷年數 | F15: 剩餘耐用年數 | H15: 總耐用年數 | J15: 買賣實例總價格(元) | M15: 11299500
A16: 100 | B16: / | C16: 3 | J16: 正常買賣總價格(元) | M16: =M15+N21+N22+N24 -> 11299500
A17: 折舊方法 | D17: 定額法 | F17: 殘餘價格率 | H17: 0.1
A18: 計 算 式 | D18: 重建成本× (1-殘價率)÷總耐用年數×已經歷年數 | J18: 土地面積(M2) | M18: 930
A20: 累積折舊額(元/M2) | F20: =(1-H17)/H16*D16*M12 -> #DIV/0! | J20: 土地正常買賣單價(元/M2) | M20: =ROUND(M16/M18,0) -> 12150
A21: 備註欄 | B21: 1.本實例移轉樓層房價(元/坪)： | H21: =M16/H7*3.3058 -> #DIV/0! | J21: 第7條、第8條修正說明及修正數： | K21: - | N21: 0
B22: 2.本實例營造單價（元/坪）： | K22: - | N22: 0
K23: - | N23: 0
K24: - | N24: 0
A25: 填寫日期： 年 月 日 承辦員： 課（股）長： 主任（局、處長）：
K26: 不動產估價師：

Sheet 92表1-2買賣實例2-建物
A1: 表1-2 買賣實例調查估價表 | I1: 年期： | J1: 1040301 | K1: 地價區段號：P020-00 | L1: 實例編號： | N1: 2
A2: 基本資料 | J2: 成 本 價 格 計 算
A3: 實例門牌 | D3: ○○市○○區○○路○○號○樓 | J3: 營造施工費標準單價(元/M2) | M3: 23500
A4: 基地坐落 | D4: ○○段○○小段○○地號 | J4: 調整單價率 | L4: 1.08 | M4: 交易日期 | N4: 103年12月12日
A5: 建號 | D5: 32 | E5: 主要構造種類 | H5: 加強磚造 | J5: 1.營造或施工費調整單價(元/M2) | M5: =ROUND(M3*L4,0) -> 25380
A6: 總樓層數 | C6: 地上層數 | D6: 4 | E6: 實例登記面積 | H6: 450 | I6: M2 | J6: 2.規劃設計費 | K6: :為營造施工費之 | L6: 0.028 | M6: =ROUND(M5*L6,0) -> 711
C7: 地下層數 | D7: 1 | E7: 實例計算面積(扣除車位) | H7: 440 | I7: M2 | J7: 3.廣告費銷售費 | K7: :實例總成本之 | L7: 0.045 | M7: =ROUND((M5+M6)*L7*(1+L10)*(1+L11)/(1-(L7+L8+L9)*(1+L10)*(1+L11)),0) -> 1499
A8: 移轉樓層 | C8: 地上第 | D8: 全 | E8: 建築工期 | H8: 1 | I8: 年 | J8: 4.管理費 | K8: :實例總成本之 | L8: 0.045 | M8: =ROUND((M5+M6)*L8*(1+L10)*(1+L11)/(1-(L7+L8+L9)*(1+L10)*(1+L11)),0) -> 1499
A9: 資本利息綜合利率計算 | B9: 資金來源 | D9: 利率 | E9: 資金比例 | G9: 加權平均利率 | J9: 5.稅捐及其他負擔 | K9: :實例總成本之 | L9: 0.012 | M9: =ROUND((M5+M6)*L9*(1+L10)*(1+L11)/(1-(L7+L8+L9)*(1+L10)*(1+L11)),0) -> 400
B10: 自有資金 | D10: 0.0136 | E10: 0.4 | G10: =ROUND(D10*E10,4) -> 0.0054 | I10: =ROUND(G10+G11+G12,4) -> 0.017 | J10: 6.資本利息 | K10: 資本利息綜合利率 | L10: =I10*G13*H8 -> 0.0085 | M10: =ROUND((M5+M6+M7+M8+M9)*L10,0) -> 251
B11: 借貸資金 | D11: 0.0289 | E11: 0.4 | G11: =ROUND(D11*E11,4) -> 0.0116 | J11: 7.開發或建築利潤 | K11: :為累計投入額之 | L11: 0.12 | M11: =ROUND((M5+M6+M7+M8+M9+M10)*L11,0) -> 3569
B12: 預售收入 | D12: 0 | E12: 0.2 | G12: =ROUND(D12*E12,4) -> 0 | J12: 實例重建成本(元/M2) | M12: =ROUND((M5+M6+M7+M8+M9)+M10+M11,0) -> 33309
B13: 分期投入資本數額及年數調整 | G13: 0.5 | J13: 實例建物成本價格(元/M2) | M13: =ROUND(M12-F20,0) -> 24575
A14: 累 積 折 舊 額 | J14: 地上□無建築改良物 ■有建築改良物(□區分所有建物■全部層數)
A15: 建築完成年月 | D15: 已經歷年數 | F15: 剩餘耐用年數 | H15: 總耐用年數 | J15: 買賣實例總價格(元) | M15: 93000000
A16: 87 | B16: / | C16: 4 | D16: 13.8 | F16: =H16-D16 -> 36.2 | H16: 50 | J16: 正常買賣總價格(元)(即買賣實例房地價格) | M16: =M15+N21+N22+N23+N24 -> 90000000
A17: 折舊方法 | D17: 定額法 | F17: 殘餘價格率 | H17: 0.05 | J17: 實例建物成本價格(總價)(不含車位) | M17: =ROUND(M13*H7,0) -> 10813000
A18: 計 算 式 | D18: 重建成本× (1-殘價率)÷總耐用年數×已經歷年數 | J18: 實例土地面積(M2) | M18: 100
A20: 累積折舊額(元/M2) | F20: =ROUND((1-H17)/H16*D16*M12,0) -> 8734 | J20: 土地正常買賣單價(元/M2) | M20: =ROUND((M16-M17)/M18,0) -> 791870
A21: 備註欄 | B21: 1.本實例移轉樓層房價(元/坪)： | H21: =ROUND(M16/H7*3.3058,-3) -> 676000 | J21: 第7條、第8條修正說明及修正數： | K21: 買賣實例售價含車位(元) | N21: -3000000
B22: 2.本實例營造單價（元/坪）： | H22: =M5*3.3058 -> 83901.204 | K22: - | N22: 0
K23: - | N23: 0
K24: - | N24: 0
A25: 填寫日期： 年 月 日 承辦員： 課（股）長： 主任（局、處長）：
K26: 不動產估價師：

Sheet 93表1-3買賣實例3-建物
A1: 表1-3 買賣實例調查估價表 | I1: 年期： | J1: 1040301 | K1: 地價區段號：P030-00 | L1: 實例編號： | N1: 3
A2: 基本資料 | J2: 成 本 價 格 計 算
A3: 實例門牌 | D3: ○○市○○區○○路○○號○樓 | J3: 營造施工費標準單價(元/M2) | M3: 30900
A4: 基地坐落 | D4: ○○段○○小段○○地號 | J4: 調整單價率 | L4: 1.1 | M4: 交易日期 | N4: 103年10月17日
A5: 建號 | D5: 210 | E5: 主要構造種類 | H5: 鋼筋混凝土加強磚造 | J5: 1.營造或施工費調整單價(元/M2) | M5: =ROUND(M3*L4,0) -> 33990
A6: 總樓層數 | C6: 地上層數 | D6: 12 | E6: 實例登記面積 | H6: 140 | I6: M2 | J6: 2.規劃設計費 | K6: :為營造施工費之 | L6: 0.025 | M6: =ROUND(M5*L6,0) -> 850
C7: 地下層數 | D7: 0 | E7: 實例計算面積(扣除車位) | H7: 128 | I7: M2 | J7: 3.廣告費銷售費 | K7: :實例總成本之 | L7: 0.045 | M7: =ROUND((M5+M6)*L7*(1+L10)*(1+L11)/(1-(L7+L8+L9)*(1+L10)*(1+L11)),0) -> 2019
A8: 移轉樓層 | C8: 地上第 | D8: 3 | E8: 建築工期 | H8: 2.2 | I8: 年 | J8: 4.管理費 | K8: :實例總成本之 | L8: 0.045 | M8: =ROUND((M5+M6)*L8*(1+L10)*(1+L11)/(1-(L7+L8+L9)*(1+L10)*(1+L11)),0) -> 2019
A9: 資本利息綜合利率計算 | B9: 資金來源 | D9: 利率 | E9: 資金比例 | G9: 加權平均利率 | J9: 5.稅捐及其他負擔 | K9: :實例總成本之 | L9: 0.01 | M9: =ROUND((M5+M6)*L9*(1+L10)*(1+L11)/(1-(L7+L8+L9)*(1+L10)*(1+L11)),0) -> 449
B10: 自有資金 | D10: 0.0136 | E10: 0.4 | G10: =ROUND(D10*E10,4) -> 0.0054 | I10: =G10+G11+G12 -> 0.017 | J10: 6.資本利息 | K10: 資本利息綜合利率 | L10: =I10*G13*H8 -> 0.0187 | M10: =ROUND((M5+M6+M7+M8+M9)*L10,0) -> 735
B11: 借貸資金 | D11: 0.0289 | E11: 0.4 | G11: =ROUND(D11*E11,4) -> 0.0116 | J11: 7.開發或建築利潤 | K11: :為累計投入額之 | L11: 0.12 | M11: =ROUND((M5+M6+M7+M8+M9+M10)*L11,0) -> 4807
B12: 預售收入 | D12: 0 | E12: 0.2 | G12: =ROUND(D12*E12,4) -> 0 | J12: 實例重建成本(元/M2) | M12: =ROUND((M5+M6+M7+M8+M9)+M10+M11,0) -> 44869
B13: 分期投入資本數額及年數調整 | G13: 0.5 | J13: 實例建物成本價格(元/M2) | M13: =ROUND(M12-F20,0) -> 34531
A14: 累 積 折 舊 額 | J14: 地上□無建築改良物 ■有建築改良物(■區分所有建物□全部層數)
A15: 建築完成年月 | D15: 已經歷年數 | F15: 剩餘耐用年數 | H15: 總耐用年數 | J15: 買賣實例總價格(元) | M15: 21000000
A16: 88 | B16: / | C16: 4 | D16: 12.8 | F16: =H16-D16 -> 37.2 | H16: 50 | J16: 正常買賣總價格(元)(即買賣實例房地價格) | M16: =M15+N21+N22+N23+N24 -> 19500000
A17: 折舊方法 | D17: 定額法 | F17: 殘餘價格率 | H17: 0.1 | J17: 實例建物成本價格(總價)(不含車位) | M17: =ROUND(M13*H7,0) -> 4419968
A18: 計 算 式 | D18: 重建成本× (1-殘價率)÷總耐用年數×已經歷年數 | J18: 實例土地持分面積(M2) | M18: 19
J19: 實例土地權利單價(元/M2) | M19: =ROUND((M16-M17)/M18,0) -> 793686
A20: 累積折舊額(元/M2) | F20: =ROUND((1-H17)/H16*D16*M12,0) -> 10338 | J20: 土地正常買賣單價(元/M2) | M20: =ROUND(M19*102%/100.73%,0) -> 803693
A21: 備註欄 | B21: 1.本實例移轉樓層房價(元/坪)： | H21: =ROUND(M16/H7*3.3058,-2) -> 503600 | J21: 第7條、第8條修正說明及修正數： | K21: 買賣實例售價含車位(元) | N21: -1500000
B22: 2.本實例營造單價（元/坪）： | H22: =M5*3.3058 -> 112364.14 | K22: - | N22: 0
K23: - | N23: 0
K24: - | N24: 0
A25: 填寫日期： 年 月 日 承辦員： 課（股）長： 主任（局、處長）：
K26: 不動產估價師：

Sheet 94表2收益法 
A1: 表2 收益法調查估價表 | H1: 年期： | J1: 1040301 | L1: 地價區段號： | P1: P040-00 | R1: 比準地宗地流水號： | U1: 0006
A2: 比準地坐落 | C2: ○○市○○區○○段○○小段○○地號 | H2: 建物門牌 | J2: ○○路○○號○樓 | R2: 建號 | T2: ○○
A3: 總收入 | B3: 收益面積(M2) | C3: 457.4 | D3: 土地持分面積(M2) | E3: 61 | F3: 總樓層 | G3: 16 | H3: 樓層別 | J3: 8 | K3: 重建成本 | P3: =C3*'95表2收益附-成本法'!M16 -> 20810785 | R3: 成本價格 | T3: =C3*'95表2收益附-成本法'!M18 -> 15191873
B4: 推估月租金(元/M2) | F4: =U24 -> 643 | K4: 估價基準日 | R4: 104年03月01日
B5: 年租金(月租金x12+權利金xMC)x面積 | F5: =ROUND(F4*12*C3,0) -> 3529298 | K5: 推估未來平均一年租金 | R5: =F5 -> 3529298
B6: 押租金(保證金) | F6: =ROUND(F4*C3*3,0) -> 882325 | K6: 一年期定存利率(%) | R6: 0.0136
B7: 押租金(保證金)運用收益 | F7: =ROUND(F6*R6,0) -> 12000 | K7: 其他收入 | R7: 0
B8: 總收入合計 | F8: =ROUND(R5+F7+R7,0) -> 3541298 | K8: 每年閒置及其他原因之收入損失月數 | R8: 1.2
B9: 有效總收入 | K9: =ROUND(F8*(1-R8/12),0) -> 3187168
A10: 總費用 | B10: 地價稅或地租 | F10: 196387 | K10: 維修費 | R10: 41623
B11: 房屋稅 | F11: 135341 | K11: 重置提撥費 | R11: =ROUND(P3*0.15*1/20*(20*2)/50,0) -> 124865
B12: 管理費 | F12: =F8*0.01 -> 35412.98 | K12: 其他費用 | R12: 0
B13: 保險費 | F13: =T3*0.00055 -> 8355.5303 | K13: 建物未來每年折舊提存率 | R13: =ROUND(((1-'95表2收益附-成本法'!H19)/'95表2收益附-成本法'!H18)/(1-((1-'95表2收益附-成本法'!H19)/'95表2收益附-成本法'!H18*'95表2收益附-成本法'!D18)),4) -> 0.0247
B14: 總費用合計 | K14: =ROUND(SUM(F10:F13)+SUM(R10:V12),0) -> 541985
A15: 淨收益 | B15: 房地淨收益 | F15: =K9-K14 -> 2645183 | K15: 建物收益資本化率決定理由 | O15: 依據不動產估價技術規則第43條第1款規定推估。
B16: 建物收益資本化率 | F16: 0.035
B17: 建物淨收益 | F17: =ROUND(T3*(F16+R13),0) -> 906955
B18: 不屬於不動產所產生其他淨收益之扣減 | F18: 0 | K18: 土地每年淨收益 | R18: =F15-F17-F18 -> 1738228
A19: 收益價格 | B19: 土地收益資本化率 | F19: 0.025 | J19: 0.025 | K19: 土地收益資本化率決定理由 | O19: 依據不動產估價技術規則第43條第2款規定推估。
B20: 土地收益總價格(元) | F20: =ROUND(R18/J19,0) -> 69529120
B21: 土地收益單價(元/M2) | F21: =ROUND(F20/E3,0) -> 1139822
B22: 考慮樓層別調整基地收益單價(元/M2) | F22: =ROUND(F21*90%/95%,0) -> 1079831
A23: 推估月租金 | B23: 收益實例編號 | C23: 地價區段號 | D23: 標的收益面積(㎡) | E23: 收益實例總租金(元/月) | F23: 收益實例月租金(元/㎡) | G23: 租金型態 | H23: 情況 調整 | I23: 租金形成日期 | J23: 價格日期調整 | K23: 區域因素調整 | M23: 個別因素調整 | O23: 調整率絕對值加總 | Q23: 比較項目修正數 | R23: 試算租金(元/㎡) | T23: 決定 權重 | U23: 推估月租金(元/㎡)
B24: 4 | C24: P040-00 | D24: 524 | E24: 330000 | F24: =ROUND(E24/D24,0) -> 630 | G24: 登錄租金 | H24: 0 | I24: 1040101 | J24: 0.025 | K24: 0 | M24: -0.02 | O24: =ABS(H24)+ABS(J24)+ABS(K24)+ABS(M24) -> 0.045 | Q24: 2 | R24: =ROUND(F24*(1+H24)*(1+J24)*(1+K24)*(1+M24),0) -> 633 | T24: 0.5 | U24: =ROUND(R24*T24+R25*T25+R26*T26,0) -> 643
B25: 7 | C25: P041-00 | D25: 613 | E25: 400000 | F25: =ROUND(E25/D25,0) -> 653 | G25: 待租價 | H25: -0.05 | I25: 1031224 | J25: 0.03 | K25: 0 | M25: 0 | O25: =ABS(H25)+ABS(J25)+ABS(K25)+ABS(M25) -> 0.08 | Q25: 2 | R25: =ROUND(F25*(1+H25)*(1+J25)*(1+K25)*(1+M25),0) -> 639 | T25: 0.3
B26: 8 | C26: P042-00 | D26: 100 | E26: 61500 | F26: =ROUND(E26/D26,0) -> 615 | G26: 詢問租金 | H26: 0.02 | I26: 1030825 | J26: 0.05 | K26: 0 | M26: 0.02 | O26: =ABS(H26)+ABS(J26)+ABS(K26)+ABS(M26) -> 0.09 | Q26: 3 | R26: =ROUND(F26*(1+H26)*(1+J26)*(1+K26)*(1+M26),0) -> 672 | T26: 0.2
A27: 收益實例依第7條、第8條修正說明 | C27: 編號7：待租租金，較鄰近正常租金偏高，參酌正常租金行情酌予調整-5%。編號8：親友關係人間之交易，較正常租金偏低，酌予調整+2%。
A30: 備註欄
A32: 填寫日期： 年 月 日 承辦員： 課（股）長： 主任（局、處長）：
N33: 不動產估價師：

Sheet 95表2收益附-成本法
A1: 表2 收益法調查估價表附表--成本法調查估價表 | K1: 比準地宗地流水號： | N1: 0006
A2: 勘估標的基本資料 | J2: 成 本 價 格 計 算
A3: 勘估標的門牌 | D3: ○○市○○區○○路○○號○樓 | J3: 營造施工費標準單價(元/M2) | M3: 33275
A4: 基地坐落 | D4: ○○段○○小段○○地號 | J4: 調整單價率 | L4: 1.03 | M4: 估價基準日 | N4: 104年03月01日
A5: 建號 | D5: 123 | E5: 主要構造種類 | H5: 鋼筋混凝土 | J5: 1.營造或施工費調整單價(元/M2) | M5: =ROUND(M3*L4,0) -> 34273
A6: 總樓層數 | C6: 地上層數 | D6: 8 | E6: 登記面積 | H6: 457.4 | I6: M2 | J6: 2.規劃設計費 | K6: :為營造施工費之 | L6: 0.025 | M6: =ROUND(M5*L6,0) -> 857
C7: 地下層數 | D7: 2 | E7: 標的計算面積(扣除車位) | H7: 418 | I7: M2 | J7: 累計投入額(1) | M7: =M5+M6 -> 35130
A8: 移轉樓層 | C8: 地上第 | D8: 8 | E8: 建築工期 | H8: 2.8 | I8: 年 | J8: 3.廣告費銷售費 | K8: :勘估標的總成本之 | L8: 0.045 | M8: =ROUND(M7*L8*J13*J15/(1-J11*J13*J15),0) -> 2047
A9: 資本利息綜合利率計算 | B9: 資金來源 | D9: 利率 | E9: 資金比例 | G9: 加權平均利率 | J9: 4.管理費 | K9: :勘估標的總成本之 | L9: 0.045 | M9: =ROUND(M7*L9*J13*J15/(1-J11*J13*J15),0) -> 2047
B10: 自有資金 | D10: 0.0136 | E10: 0.4 | G10: =ROUND(D10*E10,4) -> 0.0054 | I10: =ROUND(G10+G11+G12,4) -> 0.017 | J10: 5.稅捐及其他負擔 | K10: :勘估標的總成本之 | L10: 0.01 | M10: =ROUND(M7*L10*J13*J15/(1-J11*J13*J15),0) -> 455
B11: 借貸資金 | D11: 0.0289 | E11: 0.4 | G11: =ROUND(D11*E11,4) -> 0.0116 | J11: =SUM(L8:L10) -> 0.1 | K11: 累計投入額 | M11: =M7+M8+M9+M10 -> 39679
B12: 預售收入 | D12: 0 | E12: 0.2 | G12: =ROUND(D12*E12,4) -> 0 | J12: 6.資本利息 | K12: :為累計投入額之 | L12: =G15 -> 0.0238 | M12: =ROUND(M11*L12,0) -> 944
B13: 分期投入資本數額及年數調整 | G13: 0.5 | J13: =1+G15 -> 1.0238 | M13: =M11+M12 -> 40623
B14: 資 金 運 用 年 數 | G14: =H8 -> 2.8 | J14: 7.開發或建築利潤 | K14: :為累計投入額之 | L14: 0.12 | M14: =ROUND(M13*L14,0) -> 4875
B15: 綜合利率計算 | G15: =ROUND(I10*G13*G14,4) -> 0.0238 | J15: =1+L14 -> 1.12
A16: 累 積 折 舊 額 (元/M2) | J16: 標的重建成本(元/M2) | M16: =M11+M12+M14 -> 45498
A17: 建築完成年月 | D17: 已經歷年數 | F17: 剩餘耐用年數 | H17: 總耐用年數
A18: 85 | B18: / | C18: 10 | D18: 15 | F18: =H18-D18 -> 35 | H18: 50 | J18: 勘估標的建物成本價格(元/M2) | M18: =M16-H20 -> 33213.54
A19: 折舊方法 | D19: 定額法 | F19: 殘餘價格率 | H19: 0.1
A20: 計 算 式 | C20: 重建成本× (1-殘價率)÷總耐用年數×已經歷年數 | H20: =(1-H19)/H18*D18*M16 -> 12284.46 | J20: 標的建物成本價格(總價)(不含車位) | M20: =ROUND(M18*H7,0) -> 13883260
A21: 備註欄 | B21: 1.標的移轉樓層平均房價(元/坪)： | H21: 530000
B22: 2.本標的營造單價（元/坪）： | H22: =ROUND(M5*3.3058,0) -> 113300
A24: 填寫日期：100年3月31日 承辦員： 課（股）長：

Sheet 表5-1區域因素明細表(住)
A1: 表5-1 影響地價區域因素分析明細表（住宅用地）
A2: 案號： | C2: 比準地 | E2: 比較標的1 | F2: 實例編號 | H2: 比較標的2 | I2: 實例編號 | K2: 比較標的3 | L2: 實例編號
A3: 地價區段號
A4: 主要項目 | B4: 修正細項 | C4: 優劣等級 | E4: 優劣等級 | G4: 修正百分比 | H4: 優劣等級 | J4: 修正百分比 | K4: 優劣等級 | M4: 修正百分比
A5: 土地使用管制(1) | B5: 都市計畫（內、外）
B6: 使用分區(使用地類別)
B7: 建蔽率
B8: 容積率
B9: 有無禁止建築
B10: 有無限制建築（整體開發、面積限制、高度限制……等）
B11: 百分比小計 | G11: ％ | J11: ％ | M11: ％
A12: 交通運輸(2) | B12: 主要道路寬度
B13: 區段內道路平均寬度
B14: 接近大型車站之程度
B15: 站牌之接近程度或密集程度
B16: 交流道之有無及接近交流道之程度
B17: 區段內道路規劃及闢建程度
B18: 百分比小計 | G18: ％ | J18: ％ | M18: ％
A19: 自然條件(3) | B19: 日照
B20: 景觀
B21: 傾斜度
B22: 排水之良否
B23: 地勢
B24: 百分比小計 | G24: ％ | J24: ％ | M24: ％
A25: 土地改良(4) | B25: 建築基地改良（整平或填挖基地、開挖水溝、水土保持、鋪築道路、埋設管道、修築駁嵌等）或其他改良
B26: 百分比小計 | G26: ％ | J26: ％ | M26: ％
A27: 公共建設(5) | B27: 接近學校之程度（國小、國中、高中、大專院校）
B28: 接近市場之程度（傳統市場、超級市場、超大型購物中心）
B29: 接近公園（里鄰公園、一般公園）、廣場、徒步區之程度
B30: 接近觀光遊憩設施之程度
B31: 停車場地之便利程度
B32: 接近服務性設施的程度（郵局、銀行、醫院、機關等設施）
B33: 百分比小計 | G33: ％ | J33: ％ | M33: ％
A34: 特殊設施(6) | B34: 電業設施及公用氣體燃料設施之有無及接近程度
B35: 殯葬設施之有無及接近程度
B36: 廢棄物處理設施之有無及接近程度
B37: 百分比小計 | G37: ％ | J37: ％ | M37: ％
A38: 環境污染(7) | B38: 水污染、噪音污染、廢氣污染、廢棄物污染等之有無及接近程度
B39: 百分比小計 | G39: ％ | J39: ％ | M39: ％
A40: 其他影響因素(8)
...

Sheet 102表6宗地市價估計表格式
A1: 表6 徵收土地宗地市價估計表 | N1: 案號： | O1: ='85表7個別因素清冊格式'!O2 -> 1040301-○○-○○○ | T1: 宗地流水號： | W1: =I2 -> 0001 | X1: ~ | Y1: =Y2 -> 0005
A2: 個別因素調整項目 | C2: 比準地：宗地流水號 | E2: ='85表7個別因素清冊格式'!M3 -> 0006 | F2: 宗地流水號 | I2: ='85表7個別因素清冊格式'!D3 -> 0001 | J2: 宗地流水號 | M2: ='85表7個別因素清冊格式'!E3 -> 0002 | N2: 宗地流水號 | Q2: ='85表7個別因素清冊格式'!J3 -> 0003 | R2: 宗地流水號 | U2: ='85表7個別因素清冊格式'!K3 -> 0004 | V2: 宗地流水號 | Y2: ='85表7個別因素清冊格式'!L3 -> 0005
C3: 條件 | F3: 條件 | I3: 差異率 | J3: 條件 | M3: 差異率 | N3: 條件 | Q3: 差異率 | R3: 條件 | U3: 差異率 | V3: 條件 | Y3: 差異率
A4: 0基本資料 | C4: ○○鄉鎮市區○○段○○小段35地號 | F4: ○○鄉鎮市區○○段○○小段30地號 | J4: ○○鄉鎮市區○○段○○小段31等地號 | N4: ○○鄉鎮市區○○段○○小段32地號 | R4: ○○鄉鎮市區○○段○○小段33地號 | V4: ○○鄉鎮市區○○段○○小段34地號
A5: 比準地地價(元/M2) | C5: ='114表14比準地地價估計表'!J7 -> #REF!
A6: 1 宗地條件 | B6: 7面積(㎡) | C6: 952 | F6: 878 | I6: 0 | J6: 530 | M6: -0.01 | N6: 4456 | Q6: 0.04 | R6: 850 | U6: 0 | V6: 330 | Y6: -0.02
B7: 8寬度(M) | C7: 33 | F7: 15 | I7: -0.01 | J7: 22 | M7: -0.01 | N7: 57 | Q7: 0.01 | R7: 60 | U7: 0.02 | V7: 15 | Y7: -0.01
B8: 9深度(M) | C8: 29 | F8: 39 | I8: 0.01 | J8: 24 | M8: 0 | N8: 51 | Q8: 0.01 | R8: 10 | U8: -0.02 | V8: 22 | Y8: 0
B9: 10形狀 | C9: 方形 | F9: 方形 | I9: 0 | J9: 方形 | M9: 0 | N9: 不規則形 | Q9: -0.02 | R9: 不規則形 | U9: -0.02 | V9: 方形 | Y9: 0
B10: 11臨街情形 | C10: 單面臨街 | F10: 單面臨街 | I10: 0 | J10: 單面臨街 | M10: 0 | N10: 非臨街地 | Q10: -0.02 | R10: 非臨街地 | U10: -0.02 | V10: 單面臨街 | Y10: 0
B11: 12地勢 | C11: 平坦 | F11: 平坦 | I11: 0 | J11: 低漥 | M11: -0.03 | N11: 高亢 | Q11: -0.05 | R11: 平坦 | U11: 0 | V11: 平坦 | Y11: 0
A12: 2 道路條件 | B12: 13道路種類 | C12: 農路 | F12: 農路 | I12: 0 | J12: 農路 | M12: 0 | N12: 無 | Q12: -0.01 | R12: 無 | U12: -0.01 | V12: 農路 | Y12: 0
B13: 14面前道路寬度 | D13: 6 | E13: M | G13: 6 | H13: M | I13: 0 | K13: 6 | L13: M | M13: 0 | O13: 無 | P13: M | Q13: -0.01 | S13: 無 | T13: M | U13: -0.01 | W13: 6 | X13: M | Y13: 0
A14: 3 接近條件 | B14: 15接近學校之程度 | C14: - | D14: - | E14: M | F14: - | G14: - | H14: M | I14: - | J14: - | K14: - | L14: M | M14: - | N14: - | O14: - | P14: M | Q14: - | R14: - | S14: - | T14: M | U14: - | V14: - | W14: - | X14: M | Y14: -
B15: 16接近市場之程度 | C15: ○○市場 | D15: 1050 | E15: M | F15: ○○市場 | G15: 1055 | H15: M | I15: 0 | J15: ○○市場 | K15: 1045 | L15: M | M15: 0 | N15: ○○市場 | O15: 1060 | P15: M | Q15: 0 | R15: ○○市場 | S15: 1010 | T15: M | U15: 0 | V15: ○○市場 | W15: 1030 | X15: M | Y15: 0
B16: 17接近公園、廣場之程度 | C16: - | D16: - | E16: M | F16: - | G16: - | H16: M | I16: - | J16: - | K16: - | L16: M | M16: - | N16: - | O16: - | P16: M | Q16: - | R16: - | S16: - | T16: M | U16: - | V16: - | W16: - | X16: M | Y16: -
B17: 18接近車站之程度 | C17: ○○車站 | D17: 1000 | E17: M | F17: ○○車站 | G17: 1005 | H17: M | I17: 0 | J17: ○○車站 | K17: 995 | L17: M | M17: 0 | N17: ○○車站 | O17: 1010 | P17: M | Q17: 0 | R17: ○○車站 | S17: 960 | T17: M | U17: 0 | V17: ○○車站 | W17: 980 | X17: M | Y17: 0
B18: 19接近商圈之程度 | C18: - | D18: - | E18: M | F18: - | G18: - | H18: M | I18: - | J18: - | K18: - | L18: M | M18: - | N18: - | O18: - | P18: M | Q18: - | R18: - | S18: - | T18: M | U18: - | V18: - | W18: - | X18: M | Y18: -
A19: 4 周邊環境條件 | B19: 20嫌惡設施(類型) | C19: ○○垃圾焚化場 | D19: 2500 | E19: M | F19: ○○垃圾焚化場 | G19: 2400 | H19: M | I19: 0 | J19: ○○垃圾焚化場 | K19: 2450 | L19: M | M19: 0 | N19: ○○垃圾焚化場 | O19: 3000 | P19: M | Q19: 0.02 | R19: ○○垃圾焚化場 | S19: 2480 | T19: M | U19: 0 | V19: ○○垃圾焚化場 | W19: 2495 | X19: M | Y19: 0 | AB19: 99.13 | AC19: =ROUNDUP(AB19,0) -> 100 | AE19: =IF(F$27>100000,ROUNDUP(F$27,-3),IF(F$27>1000,ROUNDUP(F$27,-2),IF(F$27>100,ROUNDUP(F$27,-1),ROUNDUP(F$27,0)))) -> #REF!
B20: 21停車方便性 | C20: - | F20: - | I20: - | J20: - | M20: - | N20: - | Q20: - | R20: - | U20: - | V20: - | Y20: - | AB20: 811 | AC20: =ROUNDUP(AB20,-1) -> 820 | AE20: =IF(AB20>100000,ROUNDUP(AB20,-3),IF(AB20>1000,ROUNDUP(AB20,-2),IF(AB20>100,ROUNDUP(AB20,-1),ROUNDUP(AB20,0)))) -> 820
A21: 5 行政條件 | B21: 22使用分區或編定用地 | C21: 農牧用地 | F21: 農牧用地 | I21: 0 | J21: 農牧用地 | M21: 0 | N21: 林業用地 | Q21: -0.03 | R21: 農牧用地 | U21: 0 | V21: 農牧用地 | Y21: 0 | AB21: 11111 | AC21: =ROUNDUP(AB21,-2) -> 11200 | AE21: =IF(AB21>100000,ROUNDUP(AB21,-3),IF(AB21>1000,ROUNDUP(AB21,-2),IF(AB21>100,ROUNDUP(AB21,-1),ROUNDUP(AB21,0)))) -> 11200
B22: 23建蔽率(%) | C22: - | F22: - | I22: - | J22: - | M22: - | N22: - | Q22: - | R22: - | U22: - | V22: - | Y22: - | AB22: 1111111 | AC22: =ROUNDUP(AB22,-3) -> 1112000 | AE22: =IF(AB22>100000,ROUNDUP(AB22,-3),IF(AB22>1000,ROUNDUP(AB22,-2),IF(AB22>100,ROUNDUP(AB22,-1),ROUNDUP(AB22,0)))) -> 1112000
B23: 24容積率(%) | C23: - | F23: - | I23: - | J23: - | M23: - | N23: - | Q23: - | R23: - | U23: - | V23: - | Y23: -
B24: 25有無禁限建 | C24: - | F24: - | I24: - | J24: - | M24: - | N24: - | Q24: - | R24: - | U24: - | V24: - | Y24: -
A25: 6其他 | C25: - | F25: - | I25: - | J25: - | M25: - | N25: - | Q25: - | R25: - | U25: - | V25: - | Y25: -
A26: 總調整率 | F26: =SUM(I6:I25) -> 0 | J26: =SUM(M6:M25) -> -0.05 | N26: =SUM(Q6:Q25) -> -0.06 | R26: =SUM(U6:U25) -> -0.06 | V26: =SUM(Y6:Y25) -> -0.03
A27: 宗地市價試算價格(元/M2) | F27: =ROUND($C$5*(1+F26),0) -> #REF! | J27: =ROUND($C$5*(1+J26),0) -> #REF! | K27: =IF(AND(#REF!=0,#REF!=0,#REF!=0,#REF!=0,#REF!=0),1,2) -> #REF! | N27: =ROUND($C$5*(1+N26),0) -> #REF! | O27: =IF(AND(#REF!=0,#REF!=0,#REF!=0,#REF!=0,#REF!=0),1,2) -> #REF! | R27: =ROUND($C$5*(1+R26),0) -> #REF! | S27: =IF(AND(#REF!=0,#REF!=0,#REF!=0,#REF!=0,#REF!=0),1,2) -> #REF! | V27: =ROUND($C$5*(1+V26),0) -> #REF!
A28: 宗地市價(元/M2) | F28: =IF(F$27>100000,ROUNDUP(F$27,-3),IF(F$27>1000,ROUNDUP(F$27,-2),IF(F$27>100,ROUNDUP(F$27,-1),ROUNDUP(F$27,0)))) -> #REF! | J28: =IF(J$27>100000,ROUNDUP(J$27,-3),IF(J$27>1000,ROUNDUP(J$27,-2),IF(J$27>100,ROUNDUP(J$27,-1),ROUNDUP(J$27,0)))) -> #REF! | N28: =IF(N$27>100000,ROUNDUP(N$27,-3),IF(N$27>1000,ROUNDUP(N$27,-2),IF(N$27>100,ROUNDUP(N$27,-1),ROUNDUP(N$27,0)))) -> #REF! | R28: =IF(R$27>100000,ROUNDUP(R$27,-3),IF(R$27>1000,ROUNDUP(R$27,-2),IF(R$27>100,ROUNDUP(R$27,-1),ROUNDUP(R$27,0)))) -> #REF! | V28: =IF(V$27>100000,ROUNDUP(V$27,-3),IF(V$27>1000,ROUNDUP(V$27,-2),IF(V$27>100,ROUNDUP(V$27,-1),ROUNDUP(V$27,0)))) -> #REF!
A29: 備 註 欄 | B29: 各宗地
B30: 全案
A31: 填寫日期： 年 月 日 承辦員： 課（股）長： 主任（局、處長）：
M32: 不動產估價師：
A33: 填寫說明：
B34: 1.由地價查估單位取得需用土地人提供之宗地個別因素清冊後，依「土地徵收補償市價查估辦法」第20條及「影響地價個別因素評價基準表」考慮個別因素調整項目中1~5修正細項。
B36: 2.宗地市價尾數進位方式請地價單位自行依「土地徵收補償市價查估辦法」規定調整公式。

Sheet 103表9宗地市價評議表
A1: 表9 徵收土地宗地市價評議表
A2: 案號： | B2: ='85表7個別因素清冊格式'!O2 -> 1040301-○○-○○○ | G2: 估價基準日： | I2: 104.03.01
A4: 宗地流水號 | B4: 鄉鎮市區 | C4: 地價 區段號 | D4: 段小段 | E4: 地號 | F4: 面積 （M2） | G4: 擬評市價 | H4: 評定市價 | I4: 備註
G5: (元/M2) | H5: (元/M2)
A6: ='85表7個別因素清冊格式'!D$3 -> 0001 | B6: ○○鄉 | C6: P100-00 | D6: ○○段○○小段 | E6: 30 | F6: 878 | G6: ='102表6宗地市價估計表格式'!F28 -> #REF! | H6: 照案通過
A7: ='85表7個別因素清冊格式'!E3 -> 0002 | B7: ○○鄉 | C7: P100-00 | D7: ○○段○○小段 | E7: 31等 | F7: =SUM(F8:F11) -> 530 | G7: ='102表6宗地市價估計表格式'!J28 -> #REF! | H7: 15100 | I7: 合併評價單元、地勢低漥
A8: 0002-01 | B8: ○○鄉 | C8: P100-00 | D8: ○○段○○小段 | E8: 31 | F8: 120 | H8: 修正通過
A9: 0002-02 | B9: ○○鄉 | C9: P100-00 | D9: ○○段○○小段 | E9: 31-1 | F9: 210 | H9: 修正理由
A10: 0002-03 | B10: ○○鄉 | C10: P100-00 | D10: ○○段○○小段 | E10: 31-2 | F10: 110 | H10: 詳會議紀
A11: 0002-04 | B11: ○○鄉 | C11: P100-00 | D11: ○○段○○小段 | E11: 31-3 | F11: 90 | H11: 錄
A12: 0003-00 | B12: ○○鄉 | C12: P100-00 | D12: ○○段○○小段 | E12: 32 | F12: 4456 | G12: ='102表6宗地市價估計表格式'!N28 -> #REF! | H12: 照案通過 | I12: 林業用地、地勢高亢、形狀不規則、非臨街地
A13: 0004-00 | B13: ○○鄉 | C13: P100-00 | D13: ○○段○○小段 | E13: 33 | F13: 850 | G13: ='102表6宗地市價估計表格式'!R28 -> #REF! | H13: 照案通過 | I13: 形狀不規則、非臨街地
A14: 0005-00 | B14: ○○鄉 | C14: P100-00 | D14: ○○段○○小段 | E14: 34 | F14: 330 | G14: ='102表6宗地市價估計表格式'!V28 -> #REF! | H14: 照案通過 | I14: 面積、寬度
A15: 0006-00 | B15: ○○鄉 | C15: P100-00 | D15: ○○段○○小段 | E15: 35等 | F15: 952 | G15: ='102表6宗地市價估計表格式'!C5 -> #REF! | H15: 照案通過 | I15: 比準地、農牧用地、方形、單面臨街、地勢平坦
A16: 0006-01 | B16: ○○鄉 | C16: P100-00 | D16: ○○段○○小段 | E16: 35 | F16: 609
A17: 0006-02 | B17: ○○鄉 | C17: P100-00 | D17: ○○段○○小段 | E17: 35-1 | F17: 343
A18: 0007-00 | B18: ○○鄉 | C18: P100-00 | D18: ○○段○○小段 | E18: 36 | F18: 363 | G18: 13900 | H18: 照案通過 | I18: 面積、深度
A19: 0008-00 | B19: ○○鄉 | C19: P100-00 | D19: ○○段○○小段 | E19: 37 | F19: 360 | G19: 13800 | H19: 照案通過 | I19: 面積、深度、非臨街地

Sheet 104表10宗地市價清冊
A1: 表10 徵收土地宗地市價清冊
A2: 案號： | B2: ='103表9宗地市價評議表'!B2:D2 -> 1040301-○○-○○○ | E2: 估價基準日： | G2: 104.03.01
A3: ='[2]2-3個別因素清冊格式'!A2:M2 -> 興辦事業計畫名稱：
A4: 宗地流水號 | B4: 鄉鎮市區 | C4: 段小段 | D4: 地號 | E4: 面積（M2） | F4: 評定市價 | G4: 備註
F5: (元/M2)
A6: ='85表7個別因素清冊格式'!D$3 -> 0001 | B6: ○○鄉 | C6: ○○段○○小段 | D6: 30 | E6: 878 | F6: ='103表9宗地市價評議表'!G6 -> #REF!
A7: ='85表7個別因素清冊格式'!E3 -> 0002 | B7: ○○鄉 | C7: ○○段○○小段 | D7: 31等 | E7: =SUM(E8:E11) -> 530 | F7: ='103表9宗地市價評議表'!H7 -> 15100 | G7: 合併評價單元、地勢低漥
A8: 0002-01 | B8: ○○鄉 | C8: ○○段○○小段 | D8: 31 | E8: 120
A9: 0002-02 | B9: ○○鄉 | C9: ○○段○○小段 | D9: 31-1 | E9: 210
A10: 0002-03 | B10: ○○鄉 | C10: ○○段○○小段 | D10: 31-2 | E10: 110
A11: 0002-04 | B11: ○○鄉 | C11: ○○段○○小段 | D11: 31-3 | E11: 90
A12: 0003-00 | B12: ○○鄉 | C12: ○○段○○小段 | D12: 32 | E12: 4456 | F12: ='103表9宗地市價評議表'!G12 -> #REF! | G12: 林業用地、地勢高亢、形狀不規則、非臨街地
A13: 0004-00 | B13: ○○鄉 | C13: ○○段○○小段 | D13: 33 | E13: 850 | F13: ='103表9宗地市價評議表'!G13 -> #REF! | G13: 形狀不規則、非臨街地
A14: 0005-00 | B14: ○○鄉 | C14: ○○段○○小段 | D14: 34 | E14: 330 | F14: ='103表9宗地市價評議表'!G14 -> #REF! | G14: 面積、寬度
A15: 0006-00 | B15: ○○鄉 | C15: ○○段○○小段 | D15: 35等 | E15: 952 | F15: ='103表9宗地市價評議表'!G15 -> #REF! | G15: 比準地、農牧用地、方形、單面臨街、地勢平坦
A16: 0006-01 | B16: ○○鄉 | C16: ○○段○○小段 | D16: 35 | E16: 609
A17: 0006-02 | B17: ○○鄉 | C17: ○○段○○小段 | D17: 35-1 | E17: 343
A18: 0007-00 | B18: ○○鄉 | C18: ○○段○○小段 | D18: 36 | E18: 363 | F18: 13900 | G18: 面積、深度
A19: 0008-00 | B19: ○○鄉 | C19: ○○段○○小段 | D19: 37 | E19: 360 | F19: 13800 | G19: 面積、深度、非臨街地

Sheet 105表11-1計算總表
A1: 表11-1 市價變動幅度計算總表
A2: 基期： | B2: ='106表11-2計算表 '!C3 -> 1030302-1030901 | D2: 現期： | E2: ='106表11-2計算表 '!F3 -> 1030902-1040301
A3: 作業分區： | B3: TEST01 | D3: 範圍說明： | E3: TEST01全市
A4: 分類 | B4: 實例件數m | C4: 比例BR | D4: 分類 | E4: 實例件數m | F4: 比例BR
A5: 土地L | B5: =E5+E6 -> 22 | C5: =B5/$B$9 -> 0.33333333 | D5: 都內土地L1 | E5: ='106表11-2計算表 '!C40 -> 11 | F5: =E5/$B$5 -> 0.5
D6: 非都土地L2 | E6: ='107表11-2計算表(2)'!C40 -> 11 | F6: =E6/$B$5 -> 0.5
A7: 房地H | B7: =E7+E8 -> 44 | C7: =B7/$B$9 -> 0.66666667 | D7: 都內房地H1 | E7: ='108TEST01H1計算表'!C40 -> 23 | F7: =E7/$B$7 -> 0.52272727
D8: 非都房地H2 | E8: ='109TEST01H2計算表'!C40 -> 21 | F8: =E8/$B$7 -> 0.47727273
A9: 總件數 | B9: =B5+B7 -> 66 | C9: =B9/$B$9 -> 1 | D9: 總件數 | E9: =SUM(E5:E8) -> 66 | F9: =E9/$B$9 -> 1
A11: 各類別單價平均值(元/M2) | C11: 比例BR | D11: 加權後單價平均值(元/M2) | F11: 變動幅度
A12: 基期都內土地BL1 | B12: 現期都內土地TL1 | C12: BRL1 | D12: 基期土地ABL | E12: 現期土地ATL | F12: 土地變動幅度VL | G12: 市價變動幅度V
A13: ='106表11-2計算表 '!D43 -> 19620.667 | B13: ='106表11-2計算表 '!G43 -> 22465.833 | C13: =F5 -> 0.5 | D13: =A13*C13+A15*C15 -> 10355.167 | E13: =B13*C13+B15*C15 -> 12042.833 | F13: =E13/D13 -> 1.1629782 | G13: =C5*F13+F17*C7 -> 0.99766132
A14: 基期非都土地BL2 | B14: 現期非都土地TL2 | C14: BRL2
A15: ='107表11-2計算表(2)'!D43 -> 1089.6667 | B15: ='107表11-2計算表(2)'!G43 -> 1619.8333 | C15: =F6 -> 0.5
A16: 基期都內房地BH1 | B16: 現期都內房地TH1 | C16: BRH1 | D16: 基期房地ABH | E16: 現期房地ATH | F16: 房地變動幅度VH
A17: ='108TEST01H1計算表'!D43 -> 29140.333 | B17: ='108TEST01H1計算表'!G43 -> 24931.714 | C17: =F7 -> 0.52272727 | D17: =A17*C17+A19*C19 -> 23374.863 | E17: =B17*C17+B19*C19 -> 21388.067 | F17: =E17/D17 -> 0.91500287
A18: 基期非都房地BH2 | B18: 現期非都房地TH2 | C18: BRH2
A19: ='109TEST01H2計算表'!D43 -> 17060.3 | B19: ='109TEST01H2計算表'!G43 -> 17506.929 | C19: =F8 -> 0.47727273
A20: 擬評變動幅度 | E20: =G13 -> 0.99766132
A21: 備註欄
A22: 填寫日期： 年 月 日 承辦員： 課（股）長： 主任（局、處長）：

Sheet 106表11-2計算表 
A1: 表11-2 市價變動幅度計算表
B2: 作業分區： | C2: TEST01都計內L1 | D2: 範圍說明： | E2: 都計內 | G2: 單位：元/M2
A3: 期別 | B3: B基期： | C3: 1030302-1030901 | E3: T現期： | F3: 1030902-1040301
A4: 序號 | B4: 實例市價單價PLji | C4: 排序後實例市價單價PLji | D4: 百分位數25~75間市價 | E4: 實例市價單價PLji | F4: 排序後實例市價單價PLji | G4: 百分位數25~75間市價
A5: 1 | B5: 115942 | C5: 3987 | E5: 5203 | F5: 3045
A6: 2 | B6: 6215 | C6: 6095 | E6: 48326 | F6: 5203
A7: 3 | B7: 19048 | C7: 6215 | D7: 6215 | E7: 22191 | F7: 5338
A8: 4 | B8: 34783 | C8: 6917 | D8: 6917 | E8: 85474 | F8: 13918 | G8: 13918
A9: 5 | B9: 23411 | C9: 19048 | D9: 19048 | E9: 13918 | F9: 15882 | G9: 15882
A10: 6 | B10: 55691 | C10: 23411 | D10: 23411 | E10: 3045 | F10: 22191 | G10: 22191
A11: 7 | B11: 34765 | C11: 27368 | D11: 27368 | E11: 5338 | F11: 24359 | G11: 24359
A12: 8 | B12: 6917 | C12: 34765 | D12: 34765 | E12: 15882 | F12: 25645 | G12: 25645
A13: 9 | B13: 6095 | C13: 34783 | E13: 24359 | F13: 32800 | G13: 32800
A14: 10 | B14: 3987 | C14: 55691 | E14: 32800 | F14: 39171
A15: 11 | B15: 27368 | C15: 115942 | E15: 42781 | F15: 42781
A16: 12 | E16: 25645 | F16: 48326
A17: 13 | E17: 39171 | F17: 85474
A18: 14
A19: 15
A20: 16
A21: 17
A22: 18
A23: 19
A24: 20
A25: 21
A26: 22
A27: 23
A28: 24
A29: 25
... A39: 35
A40: 實例數 | C40: 11 | D40: 6 | E40: 實例數 | F40: 13 | G40: 6
A41: 第25分位 | C41: =C40/4 -> 2.75 | D41: 以排序3~8計算 | E41: 第25分位 | F41: =F40/4 -> 3.25 | G41: 以排序4~9計算
A42: 第75分位 | C42: =C40/4*3 -> 8.25 | E42: 第75分位 | F42: =F40/4*3 -> 9.75
A43: 基期市價單價平均值BL1 | D43: =AVERAGE(D7:D12) -> 19620.667 | E43: 現期市價單價平均值TL1 | G43: =AVERAGE(G8:G13) -> 22465.833
A44: 備註欄
A45: 填寫日期： 年 月 日 承辦員： 課（股）長： 主任（局、處長）：
A46: 註：實例數多於35筆請接續頁
A48: 表11-2 市價變動幅度計算表(續頁)
B49: 作業分區： | D49: 範圍說明： | G49: 單位：元/M2
A50: 期別 | B50: 基期： | E50: 現期：
...

Sheet 107表11-2計算表(2)
A1: 表11-2 市價變動幅度計算表
B2: 作業分區： | C2: TEST01非都L2 | D2: 範圍說明： | E2: 非都 | G2: 單位：元/M2
A3: 期別 | B3: B基期： | C3: 1030302-1030901 | E3: T現期： | F3: 1030902-1040301
A4: 序號 | B4: 實例市價單價PLji | C4: 排序後實例市價單價PLji | D4: 百分位數25~75間市價 | E4: 實例市價單價PLji | F4: 排序後實例市價單價PLji | G4: 百分位數25~75間市價
A5: 1 | B5: 1227 | C5: 844 | E5: 4841 | F5: 838
A6: 2 | B6: 1500 | C6: 894 | E6: 999 | F6: 875
A7: 3 | B7: 5398 | C7: 901 | D7: 901 | E7: 875 | F7: 904
A8: 4 | B8: 844 | C8: 940 | D8: 940 | E8: 3968 | F8: 999 | G8: 999
A9: 5 | B9: 894 | C9: 1040 | D9: 1040 | E9: 5246 | F9: 1004 | G9: 1004
A10: 6 | B10: 1040 | C10: 1169 | D10: 1169 | E10: 5541 | F10: 1056 | G10: 1056
A11: 7 | B11: 1169 | C11: 1227 | D11: 1227 | E11: 1394 | F11: 1298 | G11: 1298
A12: 8 | B12: 1261 | C12: 1261 | D12: 1261 | E12: 1298 | F12: 1394 | G12: 1394
A13: 9 | B13: 1265 | C13: 1265 | E13: 838 | F13: 3968 | G13: 3968
A14: 10 | B14: 901 | C14: 1500 | E14: 1004 | F14: 4841
A15: 11 | B15: 940 | C15: 5398 | E15: 1056 | F15: 5246
A16: 12 | E16: 904 | F16: 5541
A17: 13
A18: 14
A19: 15
A20: 16
A21: 17
A22: 18
A23: 19
A24: 20
A25: 21
A26: 22
A27: 23
A28: 24
... A39: 35
A40: 實例數 | C40: 11 | D40: 6 | E40: 實例數 | F40: 12 | G40: 6
A41: 第25分位 | C41: =C40/4 -> 2.75 | D41: 以排序3~8計算 | E41: 第25分位 | F41: =F40/4 -> 3 | G41: 以排序4~9計算
A42: 第75分位 | C42: =C40/4*3 -> 8.25 | E42: 第75分位 | F42: =F40/4*3 -> 9
A43: 基期市價單價平均值BL2 | D43: =AVERAGE(D7:D12) -> 1089.6667 | E43: 現期市價單價平均值TL2 | G43: =AVERAGE(G8:G13) -> 1619.8333
A44: 備註欄
A45: 填寫日期： 年 月 日 承辦員： 課（股）長： 主任（局、處長）：
A46: 註：實例數多於35筆請接續頁
A48: 表11-2 市價變動幅度計算表(續頁)
B49: 作業分區： | D49: 範圍說明： | G49: 單位：元/M2
A50: 期別 | B50: 基期： | E50: 現期：
A51: 序號 | B51: 實例市價單價PLji | C51: 排序後實例市價單價PLji | D51: 百分位數25~75間市價 | E51: 實例市價單價PLji | F51: 排序後實例市價單價PLji | G51: 百分位數25~75間市價

Sheet 108TEST01H1計算表
A1: 表11-2 市價變動幅度計算表
B2: 作業分區： | C2: TEST01都計內H1 | D2: 範圍說明： | E2: 都計內 | G2: 單位：元/M2
A3: 期別 | B3: B基期： | C3: 1030302-1030901 | E3: T現期： | F3: 1030902-1040301
A4: 序號 | B4: 實例市價單價PLji | C4: 排序後實例市價單價PLji | D4: 百分位數25~75間市價 | E4: 實例市價單價PLji | F4: 排序後實例市價單價PLji | G4: 百分位數25~75間市價
A5: 1 | B5: 47073 | C5: 14353 | E5: 30832 | F5: 13209
A6: 2 | B6: 27029 | C6: 19244 | E6: 25119 | F6: 13320
A7: 3 | B7: 34600 | C7: 21849 | E7: 30144 | F7: 13699
A8: 4 | B8: 30403 | C8: 23310 | E8: 27602 | F8: 14693
A9: 5 | B9: 34806 | C9: 23434 | E9: 21684 | F9: 16803
A10: 6 | B10: 29320 | C10: 23613 | D10: 23613 | E10: 43103 | F10: 17636
A11: 7 | B11: 39545 | C11: 25427 | D11: 25427 | E11: 31155 | F11: 18895
A12: 8 | B12: 29057 | C12: 27029 | D12: 27029 | E12: 28807 | F12: 19101 | G12: 19101
A13: 9 | B13: 31191 | C13: 27120 | D13: 27120 | E13: 38408 | F13: 19440 | G13: 19440
A14: 10 | B14: 14353 | C14: 29057 | D14: 29057 | E14: 23468 | F14: 21684 | G14: 21684
A15: 11 | B15: 31040 | C15: 29320 | D15: 29320 | E15: 14693 | F15: 22296 | G15: 22296
A16: 12 | B16: 27120 | C16: 29577 | D16: 29577 | E16: 26314 | F16: 22816 | G16: 22816
A17: 13 | B17: 19244 | C17: 30403 | D17: 30403 | E17: 17636 | F17: 23468 | G17: 23468
A18: 14 | B18: 23613 | C18: 31040 | D18: 31040 | E18: 18895 | F18: 24128 | G18: 24128
A19: 15 | B19: 21849 | C19: 31191 | D19: 31191 | E19: 13699 | F19: 25119 | G19: 25119
A20: 16 | B20: 37703 | C20: 31307 | D20: 31307 | E20: 30366 | F20: 26314 | G20: 26314
A21: 17 | B21: 23434 | C21: 34600 | D21: 34600 | E21: 16803 | F21: 27602 | G21: 27602
A22: 18 | B22: 23310 | C22: 34806 | E22: 19440 | F22: 27759 | G22: 27759
A23: 19 | B23: 25427 | C23: 35496 | E23: 22296 | F23: 28807 | G23: 28807
A24: 20 | B24: 35496 | C24: 37703 | E24: 19101 | F24: 30144 | G24: 30144
A25: 21 | B25: 31307 | C25: 39545 | E25: 24128 | F25: 30366 | G25: 30366
A26: 22 | B26: 29577 | C26: 47073 | E26: 13320 | F26: 30832
A27: 23 | B27: 63581 | C27: 63581 | E27: 136147 | F27: 31155
A28: 24 | E28: 34566 | F28: 33189
A29: 25 | E29: 13209 | F29: 34566
A30: 26 | E30: 42531 | F30: 38408
A31: 27 | E31: 27759 | F31: 42531
A32: 28 | E32: 33189 | F32: 43103
A33: 29 | E33: 22816 | F33: 136147
A34: 30
A35: 31
A36: 32
A37: 33
A38: 34
A39: 35
A40: 實例數 | C40: 23 | D40: 12 | E40: 實例數 | F40: 29 | G40: 14
...

Sheet 109TEST01H2計算表
A1: 表11-2 市價變動幅度計算表
B2: 作業分區： | C2: TEST01非都H2 | D2: 範圍說明： | E2: 非都 | G2: 單位：元/M2
A3: 期別 | B3: B基期： | C3: 1030302-1030901 | E3: T現期： | F3: 1030902-1040301
A4: 序號 | B4: 實例市價單價PLji | C4: 排序後實例市價單價PLji | D4: 百分位數25~75間市價 | E4: 實例市價單價PLji | F4: 排序後實例市價單價PLji | G4: 百分位數25~75間市價
A5: 1 | B5: 21022 | C5: 8251 | E5: 30975 | F5: 5795
A6: 2 | B6: 30248 | C6: 9609 | E6: 16087 | F6: 7953
A7: 3 | B7: 29580 | C7: 11726 | E7: 25433 | F7: 9301
A8: 4 | B8: 26702 | C8: 11739 | E8: 17968 | F8: 10032
A9: 5 | B9: 32704 | C9: 12329 | E9: 22788 | F9: 11791
A10: 6 | B10: 58267 | C10: 13151 | D10: 13151 | E10: 9301 | F10: 12458
A11: 7 | B11: 9609 | C11: 14770 | D11: 14770 | E11: 17810 | F11: 12907
A12: 8 | B12: 17569 | C12: 14998 | D12: 14998 | E12: 25305 | F12: 13110 | G12: 13110
A13: 9 | B13: 19247 | C13: 15314 | D13: 15314 | E13: 12907 | F13: 13390 | G13: 13390
A14: 10 | B14: 17348 | C14: 17348 | D14: 17348 | E14: 14759 | F14: 14473 | G14: 14473
A15: 11 | B15: 12329 | C15: 17569 | D15: 17569 | E15: 14473 | F15: 14759 | G15: 14759
A16: 12 | B16: 14770 | C16: 18399 | D16: 18399 | E16: 13390 | F16: 16087 | G16: 16087
A17: 13 | B17: 11739 | C17: 18785 | D17: 18785 | E17: 12458 | F17: 16552 | G17: 16552
A18: 14 | B18: 18399 | C18: 19247 | D18: 19247 | E18: 7953 | F18: 17810 | G18: 17810
A19: 15 | B19: 22535 | C19: 21022 | D19: 21022 | E19: 11791 | F19: 17968 | G19: 17968
A20: 16 | B20: 15314 | C20: 22535 | E20: 28808 | F20: 18783 | G20: 18783
A21: 17 | B21: 13151 | C21: 26702 | E21: 26886 | F21: 19101 | G21: 19101
A22: 18 | B22: 18785 | C22: 29580 | E22: 16552 | F22: 19309 | G22: 19309
A23: 19 | B23: 14998 | C23: 30248 | E23: 33079 | F23: 19750 | G23: 19750
A24: 20 | B24: 8251 | C24: 32704 | E24: 10032 | F24: 21217 | G24: 21217
A25: 21 | B25: 11726 | C25: 58267 | E25: 13110 | F25: 22788 | G25: 22788
A26: 22 | E26: 19750 | F26: 25305
A27: 23 | E27: 19101 | F27: 25433
A28: 24 | E28: 21217 | F28: 26886
A29: 25 | E29: 29741 | F29: 28808
A30: 26 | E30: 18783 | F30: 29105
A31: 27 | E31: 29105 | F31: 29741
A32: 28 | E32: 5795 | F32: 30975
A33: 29 | E33: 19309 | F33: 33079
A34: 30
A35: 31
A36: 32
A37: 33
A38: 34
A39: 35
A40: 實例數 | C40: 21 | D40: 10 | E40: 實例數 | F40: 29 | G40: 14
...

Sheet 110表12市價變動幅度評議表
A1: 表12 市價變動幅度評議表
A2: 基期： | B2: 1030302-1030901 | C2: 現期：1030902-1040301
A4: 作業分區 | B4: 範圍說明 | C4: 擬評變動幅度(%) | D4: 評定變動幅度(%)
A6: TEST01 | B6: TEST01全市 | C6: 99.77 | D6: 照案通過
A7: △△ | B7: △△鎮全鎮 | C7: 103.63 | D7: 照案通過
A8: ◎◎ | B8: ◎◎鎮、☆☆鎮及◇◇鎮共3鎮全部 | C8: 103.13 | D8: 照案通過
A9: ☆☆
A10: ◇◇
A11: □□-1 | B11: □□鄉內介於＊＊、※※、■■間之區域 | C11: 97.53 | D11: 照案通過
A12: □□-2 | B12: □□鄉內介於＊※、※＊、※■間之區域 | C12: 110.89 | D12: 照案通過
A13: □□-3 | B13: □□鄉內介於＊＊、※＊※、■＊■間之區域 | C13: 90.71 | D13: 照案通過

Sheet 111表13市價變動幅度表
A1: 表13 市價變動幅度表
A2: 現期： | B2: 1030902-1040301
A3: 基期： | B3: ='110表12市價變動幅度評議表'!B2 -> 1030302-1030901
A5: 作業分區 | B5: 範圍說明 | C5: 評定變動幅度(%)
A7: ○○ | B7: ='110表12市價變動幅度評議表'!B6 -> TEST01全市 | C7: 99.77
A8: △△ | B8: ='110表12市價變動幅度評議表'!B7 -> △△鎮全鎮 | C8: 103.63
A9: ◎◎ | B9: ='110表12市價變動幅度評議表'!B8 -> ◎◎鎮、☆☆鎮及◇◇鎮共3鎮全部 | C9: 103.13
A10: ☆☆
A11: ◇◇
A12: □□-1 | B12: ='110表12市價變動幅度評議表'!B11 -> □□鄉內介於＊＊、※※、■■間之區域 | C12: 97.53
A13: □□-2 | B13: ='110表12市價變動幅度評議表'!B12 -> □□鄉內介於＊※、※＊、※■間之區域 | C13: 110.89
A14: □□-3 | B14: ='110表12市價變動幅度評議表'!B13 -> □□鄉內介於＊＊、※＊※、■＊■間之區域 | C14: 90.71

Sheet 112表8-1公設平均(一般)
A1: 表8-1 公共設施保留地地價加權平均計算表
A2: 案號：1040301-○○-○○○
A3: 年期 | B3: 1040301 | C3: 區段編號 | D3: P003-00 | E3: 區段範圍 | F3: ○○○○○○○○○○○○
B4: 毗鄰各非公共設施保留地地價區段
B5: 區段號 | D5: 區段線長度(CM) | F5: 區段地價 （元/M2） | G5: 備註
A6: 區 | B6: P002-00 | D6: 8222 | F6: 4000
A7: 段 | B7: P004-00 | D7: 8313 | F7: 3500
A8: 地 | B8: P005-00 | D8: 4156 | F8: - | G8: 公共設施保留地不納入計算
A9: 價 | B9: P007-00 | D9: 4125 | F9: - | G9: 公共設施保留地不納入計算
A10: 計
A11: 算
A12: 結
A13: 果
B16: 合 計 | D16: =SUM(D6:D7) -> 16535 | F16: =ROUNDUP((D6*F6+D7*F7)/D16,-2) -> 3800
A17: 填寫日期： 年 月 日 承辦員： 課（股）長： 主任（局、處長）：
G18: 不動產估價師：

Sheet 113表8-2公設平均 (零建平均)
A1: 表8-2 公共設施保留地地價加權平均計算表(適用於土地徵收補償市價查估辦法第22條第4項)
A2: 案號：1040301-○○-○○○
A3: 年期 | B3: 1040301 | C3: 區段編號 | D3: P003-01 | F3: 區段範圍 | G3: ○○鄉○○○○○○○○○○
A4: 區 段 地 價 計 算 結 果 | B4: 距離最近之三個同性質地價區段
B5: 區段號 | D5: 區段地價（元/M2） | F5: 影響地價區域因素總修正數 | G5: 調整後區段地價 （元/M2） | H5: 備註
B6: ○○鄉P002-01 | D6: 15000 | F6: 0.0417 | G6: =ROUND(D6*(1+F6),0) -> 15626
B7: ○○鄉P002-02 | D7: 19000 | F7: -0.0629 | G7: =ROUND(D7*(1+F7),0) -> 17805
B8: ☆○鄉P004-01 | D8: 14000 | F8: 0.0523 | G8: =ROUND(D8*(1+F8),0) -> 14732
B9: 平 均 | G9: =IF(AVERAGE(G6:G8)>100000,ROUNDUP(AVERAGE(G6:G8),-3),IF(AVERAGE(G6:G8)>1000,ROUNDUP(AVERAGE(G6:G8),-2),IF(AVERAGE(G6:G8)>100,ROUNDUP(AVERAGE(G6:G8),-1),ROUNDUP(AVERAGE(G6:G8),0)))) -> 16100 | H9: 高於3區段(3,800)
A10: 填寫日期： 年 月 日 承辦員： 課（股）長： 主任（局、處長）：
H11: 不動產估價師：

Sheet 114表14比準地地價估計表
A1: 表14 比準地地價估計表
A2: 案號： | B2: 1040301-○○-○○○ | G2: 估價基準日： | I2: 1040301
A3: 區段號 | B3: 比準地基本資料 | F3: 估值(元/M2)及權重 | J3: 比準地地價(元/M2) | K3: 決定理由
B4: 宗地流水號 | C4: 鄉鎮市區 | D4: 段小段名稱 | E4: 地號 | F4: 比較價格 | G4: 權重 | H4: 收益價格 | I4: 權重
A5: P002-00 | B5: 0003 | C5: ○○鄉 | D5: ○○段○○小段 | E5: 123 | F5: 4321 | G5: 1 | H5: - | I5: 0 | J5: =IF(H5="-",IF((F5*G5)<100,ROUNDUP(F5*G5,0),IF(AND((F5*G5)>=100,(F5*G5)<1000),ROUNDUP(F5*G5,-1),IF(AND((F5*G5)>=1000,(F5*G5)<100000),ROUNDUP(F5*G5,-2),ROUNDUP(F5*G5,-3)))),IF((F5*G5+H5*I5)<100,ROUNDUP(F5*G5+H5*I5,0),IF(AND((F5*G5+H5*I5)>=100,(F5*G5+H5*I5)<1000),ROUNDUP(F5*G5+H5*I5,-1),IF(AND((F5*G5+H5*I5)>=1000,(F5*G5+H5*I5)<100000),ROUNDUP(F5*G5+H5*I5,-2),ROUNDUP(F5*G5+H5*I5,-3))))) -> 4400 | K5: ○○○○○○○○○○○○○○○○○○○○○○○○○○○○○○○○○○○○○○○○○○○○○○○○○○○○○○○○○○○○○○○○○○○○○○○○○○○○○○○○○○○○○○○○○○○○○○○○○○○○○○○○○
A6: P004-00 | B6: 0005 | C6: ○○鄉 | D6: ◎◎段◎◎小段 | E6: 456 | F6: 3513 | G6: 0.7 | H6: 3218 | I6: 0.3 | J6: =IF(H6="-",IF((F6*G6)<100,ROUNDUP(F6*G6,0),IF(AND((F6*G6)>=100,(F6*G6)<1000),ROUNDUP(F6*G6,-1),IF(AND((F6*G6)>=1000,(F6*G6)<100000),ROUNDUP(F6*G6,-2),ROUNDUP(F6*G6,-3)))),IF((F6*G6+H6*I6)<100,ROUNDUP(F6*G6+H6*I6,0),IF(AND((F6*G6+H6*I6)>=100,(F6*G6+H6*I6)<1000),ROUNDUP(F6*G6+H6*I6,-1),IF(AND((F6*G6+H6*I6)>=1000,(F6*G6+H6*I6)<100000),ROUNDUP(F6*G6+H6*I6,-2),ROUNDUP(F6*G6+H6*I6,-3))))) -> 3500 | K6: ◇◇◇◇◇◇◇◇◇◇◇◇◇◇◇◇◇◇◇◇◇◇◇◇◇◇◇◇◇◇◇◇◇◇◇◇◇◇◇◇◇◇◇◇◇◇◇◇◇◇◇◇◇◇◇◇◇◇◇◇◇◇◇◇◇◇◇◇◇◇◇◇◇◇◇◇◇◇◇◇◇◇◇◇◇◇◇◇◇◇◇◇◇◇◇◇◇◇
A7: P100-00 | B7: 0006 | C7: ○○鄉 | D7: ○○段○○小段 | E7: 35等地號 | F7: =#REF! -> #REF! | G7: 1 | H7: - | I7: 0 | J7: =IF(H7="-",IF((F7*G7)<100,ROUNDUP(F7*G7,0),IF(AND((F7*G7)>=100,(F7*G7)<1000),ROUNDUP(F7*G7,-1),IF(AND((F7*G7)>=1000,(F7*G7)<100000),ROUNDUP(F7*G7,-2),ROUNDUP(F7*G7,-3)))),IF((F7*G7+H7*I7)<100,ROUNDUP(F7*G7+H7*I7,0),IF(AND((F7*G7+H7*I7)>=100,(F7*G7+H7*I7)<1000),ROUNDUP(F7*G7+H7*I7,-1),IF(AND((F7*G7+H7*I7)>=1000,(F7*G7+H7*I7)<100000),ROUNDUP(F7*G7+H7*I7,-2),ROUNDUP(F7*G7+H7*I7,-3))))) -> #REF! | K7: △△△△△△△△△△△△△△△△△△△△△△△△△△△△△△△△△△△△△△△△△△△△△△△△△△△△△△△△△△△△△△△△△△△△△△△△△△△△△△△△△△△△△△△△△△△△△△△△△△△△△△△△△△△△△△
J8: =IF(H8="-",IF((F8*G8)<100,ROUNDUP(F8*G8,0),IF(AND((F8*G8)>=100,(F8*G8)<1000),ROUNDUP(F8*G8,-1),IF(AND((F8*G8)>=1000,(F8*G8)<100000),ROUNDUP(F8*G8,-2),ROUNDUP(F8*G8,-3)))),IF((F8*G8+H8*I8)<100,ROUNDUP(F8*G8+H8*I8,0),IF(AND((F8*G8+H8*I8)>=100,(F8*G8+H8*I8)<1000),ROUNDUP(F8*G8+H8*I8,-1),IF(AND((F8*G8+H8*I8)>=1000,(F8*G8+H8*I8)<100000),ROUNDUP(F8*G8+H8*I8,-2),ROUNDUP(F8*G8+H8*I8,-3))))) -> 0
J9: =IF(H9="-",IF((F9*G9)<100,ROUNDUP(F9*G9,0),IF(AND((F9*G9)>=100,(F9*G9)<1000),ROUNDUP(F9*G9,-1),IF(AND((F9*G9)>=1000,(F9*G9)<100000),ROUNDUP(F9*G9,-2),ROUNDUP(F9*G9,-3)))),IF((F9*G9+H9*I9)<100,ROUNDUP(F9*G9+H9*I9,0),IF(AND((F9*G9+H9*I9)>=100,(F9*G9+H9*I9)<1000),ROUNDUP(F9*G9+H9*I9,-1),IF(AND((F9*G9+H9*I9)>=1000,(F9*G9+H9*I9)<100000),ROUNDUP(F9*G9+H9*I9,-2),ROUNDUP(F9*G9+H9*I9,-3))))) -> 0
A10: 填寫日期： 年 月 日 承辦員： 課（股）長： 主任（局、處長）：
J11: 不動產估價師：
